Workbook

Sheet AÉREO REGULAR
C1: Atendimento Aéreo: | H1: Solicitado por: | M1: CIA: | P1: Divisão: | R1: CRD: | T1: Recebido em: | W1: Respondido em:
B2: 1
B3: 2
B4: 3
A6: OPÇÃO 1
A7: =COUNTIF(B9:C11," ") -> 0 | B7: Cotação: | G7: Prazo: | L7: CÓD ZENDESK | T7: Dados para reserva
A8: =COUNTIF(B13:C15," ") -> 0 | B8: CIA | D8: VOO | E8: CLASSE | F8: DATA | G8: ORIGEM | H8: DESTINO | I8: SAÍDA | J8: CHEGADA | L8: MOEDA | N8: VALOR DA PROPOSTA | O8: VALOR CLIENTE | Q8: VALOR VOO REGULAR WEBSITE
A9: IDA | L9: Dollar | O9: =N9/L11 -> 0 | U9: NOME COMPLETO | V9: DOCUMENTO | W9: VALIDADE PASSAPORTE | X9: NASCIMENTO
L10: MKUP | T10: 1
L11: 0.9 | N11: TAXA DE EMBARQUE | O11: TAXAS CLIENTE | Q11: TAXA EMBARQUE REGULAR | T11: 2
B12: =IF(A7=2,"DIRETO","CONEXÃO") -> CONEXÃO | D12: OBS.: | L12: TAXA 4BTS | O12: =N12+I17 -> 0 | T12: 3
A13: VOLTA | L13: 0.06 | T13: 4
L14: QUANT. PAX | N14: CUSTO COM TAXAS | O14: TOTAL COM TAXAS | Q14: TARIFA WEBSITE | T14: 5
N15: =SUM(N9+N12+I17) -> 0 | O15: =(O9*L13)+O9+O12 -> 0 | T15: 6
B16: =IF(A8=2,"DIRETO","CONEXÃO") -> CONEXÃO | D16: OBS.: | T16: 7
A17: QUANT. BAGAGEM | G17: TAXA DE EMISSÃO (FEE) | L17: INCENTIVO | N17: CUSTO TOTAL NET | O17: CUSTO TOTAL CLIENTE | Q17: LUCRO | T17: 8
A18: BAGAGEM EXTRA | G18: TIPO DE CABINE | I18: ECONÔMICA | L18: 0 | N18: =(N9+N12+I17)*L15 -> 0 | O18: =O15*L15 -> 0 | Q18: =O18-N18 -> 0 | T18: 9
A19: CÂMBIO | G19: STATUS | I19: RESERVADO | L19: =N19*L18 -> 0 | N19: =N18*E19 -> 0 | O19: =O18*E19 -> 0 | Q19: =O19-N19 -> 0 | T19: 10
A21: OPÇÃO 2
A22: =COUNTIF(B24:C26," ") -> 0 | B22: Cotação: | G22: Prazo: | L22: CÓD ZENDESK | T22: Dados para reserva
A23: =COUNTIF(B28:C30, " ") -> 0 | B23: CIA | D23: VOO | E23: CLASSE | F23: DATA | G23: ORIGEM | H23: DESTINO | I23: SAÍDA | J23: CHEGADA | L23: MOEDA | N23: VALOR DA PROPOSTA | O23: VALOR CLIENTE | Q23: VALOR VOO REGULAR WEBSITE
A24: IDA | L24: Dollar | O24: =N24/L26 -> 0 | U24: NOME COMPLETO | V24: DOCUMENTO | W24: VALIDADE PASSAPORTE | X24: NASCIMENTO
L25: MKUP | T25: 1
L26: 0.9 | N26: TAXA DE EMBARQUE | O26: TAXAS CLIENTE | Q26: TAXA EMBARQUE REGULAR | T26: 2
B27: =IF(A22=2,"DIRETO","CONEXÃO") -> CONEXÃO | D27: OBS.: | L27: TAXA 4BTS | O27: =N27+I32 -> 0 | T27: 3
A28: VOLTA | L28: 0.06 | T28: 4
L29: QUANT. PAX | N29: CUSTO COM TAXAS | O29: TOTAL COM TAXAS | Q29: TARIFA WEBSITE | T29: 5
N30: =SUM(N24+N27+I32) -> 0 | O30: =(O24*L28)+O24+O27 -> 0 | T30: 6
B31: =IF(A23=2,"DIRETO","CONEXÃO") -> CONEXÃO | D31: OBS.: | T31: 7
A32: QUANT. BAGAGEM | G32: TAXA DE EMISSÃO (FEE) | L32: INCENTIVO | N32: CUSTO TOTAL NET | O32: CUSTO TOTAL CLIENTE | Q32: LUCRO | T32: 8
A33: BAGAGEM EXTRA | G33: TIPO DE CABINE | I33: ECONÔMICA | L33: 0 | N33: =N30*L30 -> 0 | O33: =O30*L30 -> 0 | Q33: =O33-N33 -> 0 | T33: 9
A34: CÂMBIO | G34: STATUS | I34: RESERVADO | L34: =N34*L33 -> 0 | N34: =N33*E34 -> 0 | O34: =O33*E34 -> 0 | Q34: =O34-N34 -> 0 | T34: 10
A36: OPÇÃO 3
A37: =COUNTIF(B39:C41," ") -> 0 | B37: Cotação: | G37: Prazo: | L37: CÓD ZENDESK | T37: Dados para reserva
A38: =COUNTIF(B43:C45, " ") -> 0 | B38: CIA | D38: VOO | E38: CLASSE | F38: DATA | G38: ORIGEM | H38: DESTINO | I38: SAÍDA | J38: CHEGADA | L38: MOEDA | N38: VALOR DA PROPOSTA | O38: VALOR CLIENTE | Q38: VALOR VOO REGULAR WEBSITE
A39: IDA | L39: Dollar | O39: =N39/L41 -> 0 | U39: NOME COMPLETO | V39: DOCUMENTO | W39: VALIDADE PASSAPORTE | X39: NASCIMENTO
L40: MKUP | T40: 1
L41: 0.9 | N41: TAXA DE EMBARQUE | O41: TAXAS CLIENTE | Q41: TAXA EMBARQUE REGULAR | T41: 2
B42: =IF(A37=2,"DIRETO","CONEXÃO") -> CONEXÃO | D42: OBS.: | L42: TAXA 4BTS | O42: =N42+I47 -> 0 | T42: 3
A43: VOLTA | L43: 0.06 | T43: 4
...

Sheet PROPOSTA
A1: PROPOSTA COTAÇÃO AÉREO REGULAR
A2: =IF(K7=0,"",K7) -> OPÇÃO 1
A6: IDA | B6: CIA | D6: VOO | E6: DATA | F6: ORIGEM | G6: DESTINO | H6: SAÍDA | I6: CHEGADA | K6: Selecionar Opção
B7: =IF($K$7=DADOS!$J$3,'AÉREO REGULAR'!B9,IF($K$7=DADOS!$J$4,'AÉREO REGULAR'!B24,IF($K$7=DADOS!$J$5,'AÉREO REGULAR'!B39,IF($K$7=DADOS!$J$6,'AÉREO REGULAR'!B54,IF($K$7=DADOS!$J$7,'AÉREO REGULAR'!B69,IF($K$7=DADOS!$J$8,'AÉREO REGULAR'!B84,IF($K$7=DADOS!$J$9,'AÉREO REGULAR'!B99,IF($K$7=DADOS!$J$10,'AÉREO REGULAR'!B114,IF($K$7=DADOS!$J$11,'AÉREO REGULAR'!B129,IF($K$7=DADOS!$J$12,'AÉREO REGULAR'!B144,IF($K$7=DADOS!$J$2," "))))))))))) -> 0 | D7: =IF($K$7=DADOS!$J$3,'AÉREO REGULAR'!D9,IF($K$7=DADOS!$J$4,'AÉREO REGULAR'!D24,IF($K$7=DADOS!$J$5,'AÉREO REGULAR'!D39,IF($K$7=DADOS!$J$6,'AÉREO REGULAR'!B54,IF($K$7=DADOS!$J$7,'AÉREO REGULAR'!B69,IF($K$7=DADOS!$J$8,'AÉREO REGULAR'!D84,IF($K$7=DADOS!$J$9,'AÉREO REGULAR'!D99,IF($K$7=DADOS!$J$10,'AÉREO REGULAR'!D114,IF($K$7=DADOS!$J$11,'AÉREO REGULAR'!D129,IF($K$7=DADOS!$J$12,'AÉREO REGULAR'!D144,IF($K$7=DADOS!$J$2," "))))))))))) -> 0 | E7: =IF($K$7=DADOS!$J$3,'AÉREO REGULAR'!F9,IF($K$7=DADOS!$J$4,'AÉREO REGULAR'!F24,IF($K$7=DADOS!$J$5,'AÉREO REGULAR'!F39,IF($K$7=DADOS!$J$6,'AÉREO REGULAR'!F54,IF($K$7=DADOS!$J$7,'AÉREO REGULAR'!F69,IF($K$7=DADOS!$J$8,'AÉREO REGULAR'!F84,IF($K$7=DADOS!$J$9,'AÉREO REGULAR'!F99,IF($K$7=DADOS!$J$10,'AÉREO REGULAR'!F114,IF($K$7=DADOS!$J$11,'AÉREO REGULAR'!F129,IF($K$7=DADOS!$J$12,'AÉREO REGULAR'!F144,IF($K$7=DADOS!$J$2," "))))))))))) -> 0 | F7: =IF($K$7=DADOS!$J$3,'AÉREO REGULAR'!G9,IF($K$7=DADOS!$J$4,'AÉREO REGULAR'!G24,IF($K$7=DADOS!$J$5,'AÉREO REGULAR'!G39,IF($K$7=DADOS!$J$6,'AÉREO REGULAR'!G54,IF($K$7=DADOS!$J$7,'AÉREO REGULAR'!G69,IF($K$7=DADOS!$J$8,'AÉREO REGULAR'!G84,IF($K$7=DADOS!$J$9,'AÉREO REGULAR'!G99,IF($K$7=DADOS!$J$10,'AÉREO REGULAR'!G114,IF($K$7=DADOS!$J$11,'AÉREO REGULAR'!G129,IF($K$7=DADOS!$J$12,'AÉREO REGULAR'!G144,IF($K$7=DADOS!$J$2," "))))))))))) -> 0 | G7: =IF($K$7=DADOS!$J$3,'AÉREO REGULAR'!H9,IF($K$7=DADOS!$J$4,'AÉREO REGULAR'!H24,IF($K$7=DADOS!$J$5,'AÉREO REGULAR'!H39,IF($K$7=DADOS!$J$6,'AÉREO REGULAR'!H54,IF($K$7=DADOS!$J$7,'AÉREO REGULAR'!H69,IF($K$7=DADOS!$J$8,'AÉREO REGULAR'!H84,IF($K$7=DADOS!$J$9,'AÉREO REGULAR'!H99,IF($K$7=DADOS!$J$10,'AÉREO REGULAR'!H114,IF($K$7=DADOS!$J$11,'AÉREO REGULAR'!H129,IF($K$7=DADOS!$J$12,'AÉREO REGULAR'!H144,IF($K$7=DADOS!$J$2," "))))))))))) -> 0 | H7: =IF($K$7=DADOS!$J$3,'AÉREO REGULAR'!I9,IF($K$7=DADOS!$J$4,'AÉREO REGULAR'!I24,IF($K$7=DADOS!$J$5,'AÉREO REGULAR'!I39,IF($K$7=DADOS!$J$6,'AÉREO REGULAR'!I54,IF($K$7=DADOS!$J$7,'AÉREO REGULAR'!I69,IF($K$7=DADOS!$J$8,'AÉREO REGULAR'!I84,IF($K$7=DADOS!$J$9,'AÉREO REGULAR'!J99,IF($K$7=DADOS!$J$10,'AÉREO REGULAR'!J114,IF($K$7=DADOS!$J$11,'AÉREO REGULAR'!J129,IF($K$7=DADOS!$J$12,'AÉREO REGULAR'!J144,IF($K$7=DADOS!$J$2," "))))))))))) -> 0 | I7: =IF($K$7=DADOS!$J$3,'AÉREO REGULAR'!J9,IF($K$7=DADOS!$J$4,'AÉREO REGULAR'!J24,IF($K$7=DADOS!$J$5,'AÉREO REGULAR'!J39,IF($K$7=DADOS!$J$6,'AÉREO REGULAR'!J54,IF($K$7=DADOS!$J$7,'AÉREO REGULAR'!J69,IF($K$7=DADOS!$J$8,'AÉREO REGULAR'!J84,IF($K$7=DADOS!$J$9,'AÉREO REGULAR'!J99,IF($K$7=DADOS!$J$10,'AÉREO REGULAR'!J114,IF($K$7=DADOS!$J$11,'AÉREO REGULAR'!J129,IF($K$7=DADOS!$J$12,'AÉREO REGULAR'!J144,IF($K$7=DADOS!$J$2," "))))))))))) -> 0 | K7: OPÇÃO 1
B8: =IF($K$7=DADOS!$J$3,'AÉREO REGULAR'!B10,IF($K$7=DADOS!$J$4,'AÉREO REGULAR'!B25,IF($K$7=DADOS!$J$5,'AÉREO REGULAR'!B40,IF($K$7=DADOS!$J$6,'AÉREO REGULAR'!B55,IF($K$7=DADOS!$J$7,'AÉREO REGULAR'!B70,IF($K$7=DADOS!$J$8,'AÉREO REGULAR'!B85,IF($K$7=DADOS!$J$9,'AÉREO REGULAR'!B100,IF($K$7=DADOS!$J$10,'AÉREO REGULAR'!B115,IF($K$7=DADOS!$J$11,'AÉREO REGULAR'!B130,IF($K$7=DADOS!$J$12,'AÉREO REGULAR'!B145,IF($K$7=DADOS!$J$2," "))))))))))) -> 0 | D8: =IF($K$7=DADOS!$J$3,'AÉREO REGULAR'!D10,IF($K$7=DADOS!$J$4,'AÉREO REGULAR'!D25,IF($K$7=DADOS!$J$5,'AÉREO REGULAR'!D40,IF($K$7=DADOS!$J$6,'AÉREO REGULAR'!B55,IF($K$7=DADOS!$J$7,'AÉREO REGULAR'!B70,IF($K$7=DADOS!$J$8,'AÉREO REGULAR'!D85,IF($K$7=DADOS!$J$9,'AÉREO REGULAR'!D100,IF($K$7=DADOS!$J$10,'AÉREO REGULAR'!D115,IF($K$7=DADOS!$J$11,'AÉREO REGULAR'!D130,IF($K$7=DADOS!$J$12,'AÉREO REGULAR'!D145,IF($K$7=DADOS!$J$2," "))))))))))) -> 0 | E8: =IF($K$7=DADOS!$J$3,'AÉREO REGULAR'!F10,IF($K$7=DADOS!$J$4,'AÉREO REGULAR'!F25,IF($K$7=DADOS!$J$5,'AÉREO REGULAR'!F40,IF($K$7=DADOS!$J$6,'AÉREO REGULAR'!F55,IF($K$7=DADOS!$J$7,'AÉREO REGULAR'!F70,IF($K$7=DADOS!$J$8,'AÉREO REGULAR'!F85,IF($K$7=DADOS!$J$9,'AÉREO REGULAR'!F100,IF($K$7=DADOS!$J$10,'AÉREO REGULAR'!F115,IF($K$7=DADOS!$J$11,'AÉREO REGULAR'!F130,IF($K$7=DADOS!$J$12,'AÉREO REGULAR'!F145,IF($K$7=DADOS!$J$2," "))))))))))) -> 0 | F8: =IF($K$7=DADOS!$J$3,'AÉREO REGULAR'!G10,IF($K$7=DADOS!$J$4,'AÉREO REGULAR'!G25,IF($K$7=DADOS!$J$5,'AÉREO REGULAR'!G40,IF($K$7=DADOS!$J$6,'AÉREO REGULAR'!G55,IF($K$7=DADOS!$J$7,'AÉREO REGULAR'!G70,IF($K$7=DADOS!$J$8,'AÉREO REGULAR'!G85,IF($K$7=DADOS!$J$9,'AÉREO REGULAR'!G100,IF($K$7=DADOS!$J$10,'AÉREO REGULAR'!G115,IF($K$7=DADOS!$J$11,'AÉREO REGULAR'!G130,IF($K$7=DADOS!$J$12,'AÉREO REGULAR'!G145,IF($K$7=DADOS!$J$2," "))))))))))) -> 0 | G8: =IF($K$7=DADOS!$J$3,'AÉREO REGULAR'!H10,IF($K$7=DADOS!$J$4,'AÉREO REGULAR'!H25,IF($K$7=DADOS!$J$5,'AÉREO REGULAR'!H40,IF($K$7=DADOS!$J$6,'AÉREO REGULAR'!H55,IF($K$7=DADOS!$J$7,'AÉREO REGULAR'!H70,IF($K$7=DADOS!$J$8,'AÉREO REGULAR'!H85,IF($K$7=DADOS!$J$9,'AÉREO REGULAR'!H100,IF($K$7=DADOS!$J$10,'AÉREO REGULAR'!H115,IF($K$7=DADOS!$J$11,'AÉREO REGULAR'!H130,IF($K$7=DADOS!$J$12,'AÉREO REGULAR'!H145,IF($K$7=DADOS!$J$2," "))))))))))) -> 0 | H8: =IF($K$7=DADOS!$J$3,'AÉREO REGULAR'!I10,IF($K$7=DADOS!$J$4,'AÉREO REGULAR'!I25,IF($K$7=DADOS!$J$5,'AÉREO REGULAR'!I40,IF($K$7=DADOS!$J$6,'AÉREO REGULAR'!I55,IF($K$7=DADOS!$J$7,'AÉREO REGULAR'!I70,IF($K$7=DADOS!$J$8,'AÉREO REGULAR'!I85,IF($K$7=DADOS!$J$9,'AÉREO REGULAR'!J100,IF($K$7=DADOS!$J$10,'AÉREO REGULAR'!J115,IF($K$7=DADOS!$J$11,'AÉREO REGULAR'!J130,IF($K$7=DADOS!$J$12,'AÉREO REGULAR'!J145,IF($K$7=DADOS!$J$2," "))))))))))) -> 0 | I8: =IF($K$7=DADOS!$J$3,'AÉREO REGULAR'!J10,IF($K$7=DADOS!$J$4,'AÉREO REGULAR'!J25,IF($K$7=DADOS!$J$5,'AÉREO REGULAR'!J40,IF($K$7=DADOS!$J$6,'AÉREO REGULAR'!J55,IF($K$7=DADOS!$J$7,'AÉREO REGULAR'!J70,IF($K$7=DADOS!$J$8,'AÉREO REGULAR'!J85,IF($K$7=DADOS!$J$9,'AÉREO REGULAR'!J100,IF($K$7=DADOS!$J$10,'AÉREO REGULAR'!J115,IF($K$7=DADOS!$J$11,'AÉREO REGULAR'!J130,IF($K$7=DADOS!$J$12,'AÉREO REGULAR'!J145,IF($K$7=DADOS!$J$2," "))))))))))) -> 0
B9: =IF($K$7=DADOS!$J$3,'AÉREO REGULAR'!B11,IF($K$7=DADOS!$J$4,'AÉREO REGULAR'!B26,IF($K$7=DADOS!$J$5,'AÉREO REGULAR'!B41,IF($K$7=DADOS!$J$6,'AÉREO REGULAR'!B56,IF($K$7=DADOS!$J$7,'AÉREO REGULAR'!B71,IF($K$7=DADOS!$J$8,'AÉREO REGULAR'!B86,IF($K$7=DADOS!$J$9,'AÉREO REGULAR'!B101,IF($K$7=DADOS!$J$10,'AÉREO REGULAR'!B116,IF($K$7=DADOS!$J$11,'AÉREO REGULAR'!B131,IF($K$7=DADOS!$J$12,'AÉREO REGULAR'!B146,IF($K$7=DADOS!$J$2," "))))))))))) -> 0 | D9: =IF($K$7=DADOS!$J$3,'AÉREO REGULAR'!D11,IF($K$7=DADOS!$J$4,'AÉREO REGULAR'!D26,IF($K$7=DADOS!$J$5,'AÉREO REGULAR'!D41,IF($K$7=DADOS!$J$6,'AÉREO REGULAR'!B56,IF($K$7=DADOS!$J$7,'AÉREO REGULAR'!B71,IF($K$7=DADOS!$J$8,'AÉREO REGULAR'!D86,IF($K$7=DADOS!$J$9,'AÉREO REGULAR'!D101,IF($K$7=DADOS!$J$10,'AÉREO REGULAR'!D116,IF($K$7=DADOS!$J$11,'AÉREO REGULAR'!D131,IF($K$7=DADOS!$J$12,'AÉREO REGULAR'!D146,IF($K$7=DADOS!$J$2," "))))))))))) -> 0 | E9: =IF($K$7=DADOS!$J$3,'AÉREO REGULAR'!F11,IF($K$7=DADOS!$J$4,'AÉREO REGULAR'!F26,IF($K$7=DADOS!$J$5,'AÉREO REGULAR'!F41,IF($K$7=DADOS!$J$6,'AÉREO REGULAR'!F56,IF($K$7=DADOS!$J$7,'AÉREO REGULAR'!F71,IF($K$7=DADOS!$J$8,'AÉREO REGULAR'!F86,IF($K$7=DADOS!$J$9,'AÉREO REGULAR'!F101,IF($K$7=DADOS!$J$10,'AÉREO REGULAR'!F116,IF($K$7=DADOS!$J$11,'AÉREO REGULAR'!F131,IF($K$7=DADOS!$J$12,'AÉREO REGULAR'!F146,IF($K$7=DADOS!$J$2," "))))))))))) -> 0 | F9: =IF($K$7=DADOS!$J$3,'AÉREO REGULAR'!G11,IF($K$7=DADOS!$J$4,'AÉREO REGULAR'!G26,IF($K$7=DADOS!$J$5,'AÉREO REGULAR'!G41,IF($K$7=DADOS!$J$6,'AÉREO REGULAR'!G56,IF($K$7=DADOS!$J$7,'AÉREO REGULAR'!G71,IF($K$7=DADOS!$J$8,'AÉREO REGULAR'!G86,IF($K$7=DADOS!$J$9,'AÉREO REGULAR'!G101,IF($K$7=DADOS!$J$10,'AÉREO REGULAR'!G116,IF($K$7=DADOS!$J$11,'AÉREO REGULAR'!G131,IF($K$7=DADOS!$J$12,'AÉREO REGULAR'!G146,IF($K$7=DADOS!$J$2," "))))))))))) -> 0 | G9: =IF($K$7=DADOS!$J$3,'AÉREO REGULAR'!H11,IF($K$7=DADOS!$J$4,'AÉREO REGULAR'!H26,IF($K$7=DADOS!$J$5,'AÉREO REGULAR'!H41,IF($K$7=DADOS!$J$6,'AÉREO REGULAR'!H56,IF($K$7=DADOS!$J$7,'AÉREO REGULAR'!H71,IF($K$7=DADOS!$J$8,'AÉREO REGULAR'!H86,IF($K$7=DADOS!$J$9,'AÉREO REGULAR'!H101,IF($K$7=DADOS!$J$10,'AÉREO REGULAR'!H116,IF($K$7=DADOS!$J$11,'AÉREO REGULAR'!H131,IF($K$7=DADOS!$J$12,'AÉREO REGULAR'!H146,IF($K$7=DADOS!$J$2," "))))))))))) -> 0 | H9: =IF($K$7=DADOS!$J$3,'AÉREO REGULAR'!I11,IF($K$7=DADOS!$J$4,'AÉREO REGULAR'!I26,IF($K$7=DADOS!$J$5,'AÉREO REGULAR'!I41,IF($K$7=DADOS!$J$6,'AÉREO REGULAR'!I56,IF($K$7=DADOS!$J$7,'AÉREO REGULAR'!I71,IF($K$7=DADOS!$J$8,'AÉREO REGULAR'!I86,IF($K$7=DADOS!$J$9,'AÉREO REGULAR'!J101,IF($K$7=DADOS!$J$10,'AÉREO REGULAR'!J116,IF($K$7=DADOS!$J$11,'AÉREO REGULAR'!J131,IF($K$7=DADOS!$J$12,'AÉREO REGULAR'!J146,IF($K$7=DADOS!$J$2," "))))))))))) -> 0 | I9: =IF($K$7=DADOS!$J$3,'AÉREO REGULAR'!J11,IF($K$7=DADOS!$J$4,'AÉREO REGULAR'!J26,IF($K$7=DADOS!$J$5,'AÉREO REGULAR'!J41,IF($K$7=DADOS!$J$6,'AÉREO REGULAR'!J56,IF($K$7=DADOS!$J$7,'AÉREO REGULAR'!J71,IF($K$7=DADOS!$J$8,'AÉREO REGULAR'!J86,IF($K$7=DADOS!$J$9,'AÉREO REGULAR'!J101,IF($K$7=DADOS!$J$10,'AÉREO REGULAR'!J116,IF($K$7=DADOS!$J$11,'AÉREO REGULAR'!J131,IF($K$7=DADOS!$J$12,'AÉREO REGULAR'!J146,IF($K$7=DADOS!$J$2," "))))))))))) -> 0
A10: VOLTA | B10: =IF($K$7=DADOS!$J$3,'AÉREO REGULAR'!B12,IF($K$7=DADOS!$J$4,'AÉREO REGULAR'!B27,IF($K$7=DADOS!$J$5,'AÉREO REGULAR'!B42,IF($K$7=DADOS!$J$6,'AÉREO REGULAR'!B57,IF($K$7=DADOS!$J$7,'AÉREO REGULAR'!B72,IF($K$7=DADOS!$J$8,'AÉREO REGULAR'!B87,IF($K$7=DADOS!$J$9,'AÉREO REGULAR'!B102,IF($K$7=DADOS!$J$10,'AÉREO REGULAR'!B117,IF($K$7=DADOS!$J$11,'AÉREO REGULAR'!B132,IF($K$7=DADOS!$J$12,'AÉREO REGULAR'!B147,IF($K$7=DADOS!$J$2," "))))))))))) -> CONEXÃO | D10: OBS.: | E10: =IF($K$7=DADOS!$J$3,'AÉREO REGULAR'!E12,IF($K$7=DADOS!$J$4,'AÉREO REGULAR'!E27,IF($K$7=DADOS!$J$5,'AÉREO REGULAR'!E42,IF($K$7=DADOS!$J$6,'AÉREO REGULAR'!E57,IF($K$7=DADOS!$J$7,'AÉREO REGULAR'!E72,IF($K$7=DADOS!$J$8,'AÉREO REGULAR'!E87,IF($K$7=DADOS!$J$9,'AÉREO REGULAR'!E102,IF($K$7=DADOS!$J$10,'AÉREO REGULAR'!E117,IF($K$7=DADOS!$J$11,'AÉREO REGULAR'!E132,IF($K$7=DADOS!$J$12,'AÉREO REGULAR'!E147,IF($K$7=DADOS!$J$2," "))))))))))) -> 0
B11: CIA | D11: VOO | E11: DATA | F11: ORIGEM | G11: DESTINO | H11: SAÍDA | I11: CHEGADA
B12: =IF($K$7=DADOS!$J$3,'AÉREO REGULAR'!B13,IF($K$7=DADOS!$J$4,'AÉREO REGULAR'!B28,IF($K$7=DADOS!$J$5,'AÉREO REGULAR'!B43,IF($K$7=DADOS!$J$6,'AÉREO REGULAR'!B58,IF($K$7=DADOS!$J$7,'AÉREO REGULAR'!B73,IF($K$7=DADOS!$J$8,'AÉREO REGULAR'!B88,IF($K$7=DADOS!$J$9,'AÉREO REGULAR'!B103,IF($K$7=DADOS!$J$10,'AÉREO REGULAR'!B118,IF($K$7=DADOS!$J$11,'AÉREO REGULAR'!B133,IF($K$7=DADOS!$J$12,'AÉREO REGULAR'!B148,IF($K$7=DADOS!$J$2," "))))))))))) -> 0 | D12: =IF($K$7=DADOS!$J$3,'AÉREO REGULAR'!D13,IF($K$7=DADOS!$J$4,'AÉREO REGULAR'!D28,IF($K$7=DADOS!$J$5,'AÉREO REGULAR'!D43,IF($K$7=DADOS!$J$6,'AÉREO REGULAR'!B58,IF($K$7=DADOS!$J$7,'AÉREO REGULAR'!B73,IF($K$7=DADOS!$J$8,'AÉREO REGULAR'!D88,IF($K$7=DADOS!$J$9,'AÉREO REGULAR'!D103,IF($K$7=DADOS!$J$10,'AÉREO REGULAR'!D118,IF($K$7=DADOS!$J$11,'AÉREO REGULAR'!D133,IF($K$7=DADOS!$J$12,'AÉREO REGULAR'!D148,IF($K$7=DADOS!$J$2," "))))))))))) -> 0 | E12: =IF($K$7=DADOS!$J$3,'AÉREO REGULAR'!F13,IF($K$7=DADOS!$J$4,'AÉREO REGULAR'!F28,IF($K$7=DADOS!$J$5,'AÉREO REGULAR'!F43,IF($K$7=DADOS!$J$6,'AÉREO REGULAR'!F58,IF($K$7=DADOS!$J$7,'AÉREO REGULAR'!F73,IF($K$7=DADOS!$J$8,'AÉREO REGULAR'!F88,IF($K$7=DADOS!$J$9,'AÉREO REGULAR'!F103,IF($K$7=DADOS!$J$10,'AÉREO REGULAR'!F118,IF($K$7=DADOS!$J$11,'AÉREO REGULAR'!F133,IF($K$7=DADOS!$J$12,'AÉREO REGULAR'!F148,IF($K$7=DADOS!$J$2," "))))))))))) -> 0 | F12: =IF($K$7=DADOS!$J$3,'AÉREO REGULAR'!G14,IF($K$7=DADOS!$J$4,'AÉREO REGULAR'!G25,IF($K$7=DADOS!$J$5,'AÉREO REGULAR'!G42,IF($K$7=DADOS!$J$6,'AÉREO REGULAR'!G58,IF($K$7=DADOS!$J$7,'AÉREO REGULAR'!G73,IF($K$7=DADOS!$J$8,'AÉREO REGULAR'!G88,IF($K$7=DADOS!$J$9,'AÉREO REGULAR'!G103,IF($K$7=DADOS!$J$10,'AÉREO REGULAR'!G118,IF($K$7=DADOS!$J$11,'AÉREO REGULAR'!G133,IF($K$7=DADOS!$J$12,'AÉREO REGULAR'!G148,IF($K$7=DADOS!$J$2," "))))))))))) -> 0 | G12: =IF($K$7=DADOS!$J$3,'AÉREO REGULAR'!H13,IF($K$7=DADOS!$J$4,'AÉREO REGULAR'!H28,IF($K$7=DADOS!$J$5,'AÉREO REGULAR'!H43,IF($K$7=DADOS!$J$6,'AÉREO REGULAR'!H58,IF($K$7=DADOS!$J$7,'AÉREO REGULAR'!H73,IF($K$7=DADOS!$J$8,'AÉREO REGULAR'!H88,IF($K$7=DADOS!$J$9,'AÉREO REGULAR'!H103,IF($K$7=DADOS!$J$10,'AÉREO REGULAR'!H118,IF($K$7=DADOS!$J$11,'AÉREO REGULAR'!H133,IF($K$7=DADOS!$J$12,'AÉREO REGULAR'!H148,IF($K$7=DADOS!$J$2," "))))))))))) -> 0 | H12: =IF($K$7=DADOS!$J$3,'AÉREO REGULAR'!I13,IF($K$7=DADOS!$J$4,'AÉREO REGULAR'!I28,IF($K$7=DADOS!$J$5,'AÉREO REGULAR'!I43,IF($K$7=DADOS!$J$6,'AÉREO REGULAR'!I58,IF($K$7=DADOS!$J$7,'AÉREO REGULAR'!I73,IF($K$7=DADOS!$J$8,'AÉREO REGULAR'!I88,IF($K$7=DADOS!$J$9,'AÉREO REGULAR'!J103,IF($K$7=DADOS!$J$10,'AÉREO REGULAR'!J118,IF($K$7=DADOS!$J$11,'AÉREO REGULAR'!J133,IF($K$7=DADOS!$J$12,'AÉREO REGULAR'!J148,IF($K$7=DADOS!$J$2," "))))))))))) -> 0 | I12: =IF($K$7=DADOS!$J$3,'AÉREO REGULAR'!J13,IF($K$7=DADOS!$J$4,'AÉREO REGULAR'!J28,IF($K$7=DADOS!$J$5,'AÉREO REGULAR'!J43,IF($K$7=DADOS!$J$6,'AÉREO REGULAR'!J58,IF($K$7=DADOS!$J$7,'AÉREO REGULAR'!J73,IF($K$7=DADOS!$J$8,'AÉREO REGULAR'!J88,IF($K$7=DADOS!$J$9,'AÉREO REGULAR'!J103,IF($K$7=DADOS!$J$10,'AÉREO REGULAR'!J118,IF($K$7=DADOS!$J$11,'AÉREO REGULAR'!J133,IF($K$7=DADOS!$J$12,'AÉREO REGULAR'!J148,IF($K$7=DADOS!$J$2," "))))))))))) -> 0
B13: =IF($K$7=DADOS!$J$3,'AÉREO REGULAR'!B14,IF($K$7=DADOS!$J$4,'AÉREO REGULAR'!B29,IF($K$7=DADOS!$J$5,'AÉREO REGULAR'!B44,IF($K$7=DADOS!$J$6,'AÉREO REGULAR'!B59,IF($K$7=DADOS!$J$7,'AÉREO REGULAR'!B74,IF($K$7=DADOS!$J$8,'AÉREO REGULAR'!B89,IF($K$7=DADOS!$J$9,'AÉREO REGULAR'!B104,IF($K$7=DADOS!$J$10,'AÉREO REGULAR'!B119,IF($K$7=DADOS!$J$11,'AÉREO REGULAR'!B134,IF($K$7=DADOS!$J$12,'AÉREO REGULAR'!B149,IF($K$7=DADOS!$J$2," "))))))))))) -> 0 | D13: =IF($K$7=DADOS!$J$3,'AÉREO REGULAR'!D14,IF($K$7=DADOS!$J$4,'AÉREO REGULAR'!D29,IF($K$7=DADOS!$J$5,'AÉREO REGULAR'!D44,IF($K$7=DADOS!$J$6,'AÉREO REGULAR'!B59,IF($K$7=DADOS!$J$7,'AÉREO REGULAR'!B74,IF($K$7=DADOS!$J$8,'AÉREO REGULAR'!D89,IF($K$7=DADOS!$J$9,'AÉREO REGULAR'!D104,IF($K$7=DADOS!$J$10,'AÉREO REGULAR'!D119,IF($K$7=DADOS!$J$11,'AÉREO REGULAR'!D134,IF($K$7=DADOS!$J$12,'AÉREO REGULAR'!D149,IF($K$7=DADOS!$J$2," "))))))))))) -> 0 | E13: =IF($K$7=DADOS!$J$3,'AÉREO REGULAR'!F14,IF($K$7=DADOS!$J$4,'AÉREO REGULAR'!F29,IF($K$7=DADOS!$J$5,'AÉREO REGULAR'!F44,IF($K$7=DADOS!$J$6,'AÉREO REGULAR'!F59,IF($K$7=DADOS!$J$7,'AÉREO REGULAR'!F74,IF($K$7=DADOS!$J$8,'AÉREO REGULAR'!F89,IF($K$7=DADOS!$J$9,'AÉREO REGULAR'!F104,IF($K$7=DADOS!$J$10,'AÉREO REGULAR'!F119,IF($K$7=DADOS!$J$11,'AÉREO REGULAR'!F134,IF($K$7=DADOS!$J$12,'AÉREO REGULAR'!F149,IF($K$7=DADOS!$J$2," "))))))))))) -> 0 | F13: =IF($K$7=DADOS!$J$3,'AÉREO REGULAR'!G15,IF($K$7=DADOS!$J$4,'AÉREO REGULAR'!G26,IF($K$7=DADOS!$J$5,'AÉREO REGULAR'!G43,IF($K$7=DADOS!$J$6,'AÉREO REGULAR'!G59,IF($K$7=DADOS!$J$7,'AÉREO REGULAR'!G74,IF($K$7=DADOS!$J$8,'AÉREO REGULAR'!G89,IF($K$7=DADOS!$J$9,'AÉREO REGULAR'!G104,IF($K$7=DADOS!$J$10,'AÉREO REGULAR'!G119,IF($K$7=DADOS!$J$11,'AÉREO REGULAR'!G134,IF($K$7=DADOS!$J$12,'AÉREO REGULAR'!G149,IF($K$7=DADOS!$J$2," "))))))))))) -> 0 | G13: =IF($K$7=DADOS!$J$3,'AÉREO REGULAR'!H14,IF($K$7=DADOS!$J$4,'AÉREO REGULAR'!H29,IF($K$7=DADOS!$J$5,'AÉREO REGULAR'!H44,IF($K$7=DADOS!$J$6,'AÉREO REGULAR'!H59,IF($K$7=DADOS!$J$7,'AÉREO REGULAR'!H74,IF($K$7=DADOS!$J$8,'AÉREO REGULAR'!H89,IF($K$7=DADOS!$J$9,'AÉREO REGULAR'!H104,IF($K$7=DADOS!$J$10,'AÉREO REGULAR'!H119,IF($K$7=DADOS!$J$11,'AÉREO REGULAR'!H134,IF($K$7=DADOS!$J$12,'AÉREO REGULAR'!H149,IF($K$7=DADOS!$J$2," "))))))))))) -> 0 | H13: =IF($K$7=DADOS!$J$3,'AÉREO REGULAR'!I14,IF($K$7=DADOS!$J$4,'AÉREO REGULAR'!I29,IF($K$7=DADOS!$J$5,'AÉREO REGULAR'!I44,IF($K$7=DADOS!$J$6,'AÉREO REGULAR'!I59,IF($K$7=DADOS!$J$7,'AÉREO REGULAR'!I74,IF($K$7=DADOS!$J$8,'AÉREO REGULAR'!I89,IF($K$7=DADOS!$J$9,'AÉREO REGULAR'!J104,IF($K$7=DADOS!$J$10,'AÉREO REGULAR'!J119,IF($K$7=DADOS!$J$11,'AÉREO REGULAR'!J134,IF($K$7=DADOS!$J$12,'AÉREO REGULAR'!J149,IF($K$7=DADOS!$J$2," "))))))))))) -> 0 | I13: =IF($K$7=DADOS!$J$3,'AÉREO REGULAR'!J14,IF($K$7=DADOS!$J$4,'AÉREO REGULAR'!J29,IF($K$7=DADOS!$J$5,'AÉREO REGULAR'!J44,IF($K$7=DADOS!$J$6,'AÉREO REGULAR'!J59,IF($K$7=DADOS!$J$7,'AÉREO REGULAR'!J74,IF($K$7=DADOS!$J$8,'AÉREO REGULAR'!J89,IF($K$7=DADOS!$J$9,'AÉREO REGULAR'!J104,IF($K$7=DADOS!$J$10,'AÉREO REGULAR'!J119,IF($K$7=DADOS!$J$11,'AÉREO REGULAR'!J134,IF($K$7=DADOS!$J$12,'AÉREO REGULAR'!J149,IF($K$7=DADOS!$J$2," "))))))))))) -> 0
B14: =IF($K$7=DADOS!$J$3,'AÉREO REGULAR'!B15,IF($K$7=DADOS!$J$4,'AÉREO REGULAR'!B30,IF($K$7=DADOS!$J$5,'AÉREO REGULAR'!B45,IF($K$7=DADOS!$J$6,'AÉREO REGULAR'!B60,IF($K$7=DADOS!$J$7,'AÉREO REGULAR'!B75,IF($K$7=DADOS!$J$8,'AÉREO REGULAR'!B90,IF($K$7=DADOS!$J$9,'AÉREO REGULAR'!B105,IF($K$7=DADOS!$J$10,'AÉREO REGULAR'!B120,IF($K$7=DADOS!$J$11,'AÉREO REGULAR'!B135,IF($K$7=DADOS!$J$12,'AÉREO REGULAR'!B150,IF($K$7=DADOS!$J$2," "))))))))))) -> 0 | D14: =IF($K$7=DADOS!$J$3,'AÉREO REGULAR'!D15,IF($K$7=DADOS!$J$4,'AÉREO REGULAR'!D30,IF($K$7=DADOS!$J$5,'AÉREO REGULAR'!D45,IF($K$7=DADOS!$J$6,'AÉREO REGULAR'!B60,IF($K$7=DADOS!$J$7,'AÉREO REGULAR'!B75,IF($K$7=DADOS!$J$8,'AÉREO REGULAR'!D90,IF($K$7=DADOS!$J$9,'AÉREO REGULAR'!D105,IF($K$7=DADOS!$J$10,'AÉREO REGULAR'!D120,IF($K$7=DADOS!$J$11,'AÉREO REGULAR'!D135,IF($K$7=DADOS!$J$12,'AÉREO REGULAR'!D150,IF($K$7=DADOS!$J$2," "))))))))))) -> 0 | E14: =IF($K$7=DADOS!$J$3,'AÉREO REGULAR'!F15,IF($K$7=DADOS!$J$4,'AÉREO REGULAR'!F30,IF($K$7=DADOS!$J$5,'AÉREO REGULAR'!F45,IF($K$7=DADOS!$J$6,'AÉREO REGULAR'!F60,IF($K$7=DADOS!$J$7,'AÉREO REGULAR'!F75,IF($K$7=DADOS!$J$8,'AÉREO REGULAR'!F90,IF($K$7=DADOS!$J$9,'AÉREO REGULAR'!F105,IF($K$7=DADOS!$J$10,'AÉREO REGULAR'!F120,IF($K$7=DADOS!$J$11,'AÉREO REGULAR'!F135,IF($K$7=DADOS!$J$12,'AÉREO REGULAR'!F150,IF($K$7=DADOS!$J$2," "))))))))))) -> 0 | F14: =IF($K$7=DADOS!$J$3,'AÉREO REGULAR'!G16,IF($K$7=DADOS!$J$4,'AÉREO REGULAR'!G27,IF($K$7=DADOS!$J$5,'AÉREO REGULAR'!G44,IF($K$7=DADOS!$J$6,'AÉREO REGULAR'!G60,IF($K$7=DADOS!$J$7,'AÉREO REGULAR'!G75,IF($K$7=DADOS!$J$8,'AÉREO REGULAR'!G90,IF($K$7=DADOS!$J$9,'AÉREO REGULAR'!G105,IF($K$7=DADOS!$J$10,'AÉREO REGULAR'!G120,IF($K$7=DADOS!$J$11,'AÉREO REGULAR'!G135,IF($K$7=DADOS!$J$12,'AÉREO REGULAR'!G150,IF($K$7=DADOS!$J$2," "))))))))))) -> 0 | G14: =IF($K$7=DADOS!$J$3,'AÉREO REGULAR'!H15,IF($K$7=DADOS!$J$4,'AÉREO REGULAR'!H30,IF($K$7=DADOS!$J$5,'AÉREO REGULAR'!H45,IF($K$7=DADOS!$J$6,'AÉREO REGULAR'!H60,IF($K$7=DADOS!$J$7,'AÉREO REGULAR'!H75,IF($K$7=DADOS!$J$8,'AÉREO REGULAR'!H90,IF($K$7=DADOS!$J$9,'AÉREO REGULAR'!H105,IF($K$7=DADOS!$J$10,'AÉREO REGULAR'!H120,IF($K$7=DADOS!$J$11,'AÉREO REGULAR'!H135,IF($K$7=DADOS!$J$12,'AÉREO REGULAR'!H150,IF($K$7=DADOS!$J$2," "))))))))))) -> 0 | H14: =IF($K$7=DADOS!$J$3,'AÉREO REGULAR'!I15,IF($K$7=DADOS!$J$4,'AÉREO REGULAR'!I30,IF($K$7=DADOS!$J$5,'AÉREO REGULAR'!I45,IF($K$7=DADOS!$J$6,'AÉREO REGULAR'!I60,IF($K$7=DADOS!$J$7,'AÉREO REGULAR'!I75,IF($K$7=DADOS!$J$8,'AÉREO REGULAR'!I90,IF($K$7=DADOS!$J$9,'AÉREO REGULAR'!J105,IF($K$7=DADOS!$J$10,'AÉREO REGULAR'!J120,IF($K$7=DADOS!$J$11,'AÉREO REGULAR'!J135,IF($K$7=DADOS!$J$12,'AÉREO REGULAR'!J150,IF($K$7=DADOS!$J$2," "))))))))))) -> 0 | I14: =IF($K$7=DADOS!$J$3,'AÉREO REGULAR'!J15,IF($K$7=DADOS!$J$4,'AÉREO REGULAR'!J30,IF($K$7=DADOS!$J$5,'AÉREO REGULAR'!J45,IF($K$7=DADOS!$J$6,'AÉREO REGULAR'!J60,IF($K$7=DADOS!$J$7,'AÉREO REGULAR'!J75,IF($K$7=DADOS!$J$8,'AÉREO REGULAR'!J90,IF($K$7=DADOS!$J$9,'AÉREO REGULAR'!J105,IF($K$7=DADOS!$J$10,'AÉREO REGULAR'!J120,IF($K$7=DADOS!$J$11,'AÉREO REGULAR'!J135,IF($K$7=DADOS!$J$12,'AÉREO REGULAR'!J150,IF($K$7=DADOS!$J$2," "))))))))))) -> 0
B15: =IF($K$7=DADOS!$J$3,'AÉREO REGULAR'!B16,IF($K$7=DADOS!$J$4,'AÉREO REGULAR'!B31,IF($K$7=DADOS!$J$5,'AÉREO REGULAR'!B46,IF($K$7=DADOS!$J$6,'AÉREO REGULAR'!B61,IF($K$7=DADOS!$J$7,'AÉREO REGULAR'!B76,IF($K$7=DADOS!$J$8,'AÉREO REGULAR'!B91,IF($K$7=DADOS!$J$9,'AÉREO REGULAR'!B106,IF($K$7=DADOS!$J$10,'AÉREO REGULAR'!B121,IF($K$7=DADOS!$J$11,'AÉREO REGULAR'!B136,IF($K$7=DADOS!$J$12,'AÉREO REGULAR'!B151,IF($K$7=DADOS!$J$2," "))))))))))) -> CONEXÃO | D15: OBS.: | E15: =IF($K$7=DADOS!$J$3,'AÉREO REGULAR'!E16,IF($K$7=DADOS!$J$4,'AÉREO REGULAR'!E31,IF($K$7=DADOS!$J$5,'AÉREO REGULAR'!E46,IF($K$7=DADOS!$J$6,'AÉREO REGULAR'!E61,IF($K$7=DADOS!$J$7,'AÉREO REGULAR'!E76,IF($K$7=DADOS!$J$8,'AÉREO REGULAR'!E91,IF($K$7=DADOS!$J$9,'AÉREO REGULAR'!E106,IF($K$7=DADOS!$J$10,'AÉREO REGULAR'!E121,IF($K$7=DADOS!$J$11,'AÉREO REGULAR'!E136,IF($K$7=DADOS!$J$12,'AÉREO REGULAR'!E151,IF($K$7=DADOS!$J$2," "))))))))))) -> 0
A17: INFORMAÇÕES ADCIONAIS
A18: - Certifique-se que não houve alteração no terminal de embarque indicado antes da viagem. - Para viagens nacionais, apresentar cédula de identidade ou CNH original com foto. - Para viagens internacionais, verificar se o país a ser visitado exige passaporte, vacina ou visto de entrada. - Para visualizar as informações sobre vistos e vacinas. http://www.iatatravelcentre.com/passport-visa-health-travel-document-requirements.htm - Para visualizar informações sobre o país de destino. http://www.iatatravelcentre.com/customs-currency-airport-tax-regulations.htm - A apresentação para embarque deve ocorrer com 2 horas de antecedência para voos domésticos e 3 horas para voos internacionais, -Lembrando que o terminal de embarque está sujeito a alteração. - Recomendamos que consulte a sua cia aérea para condições e regras de embarque.
A29: Nada reservado, apenas cotado. Sujeito a disponibilidade e Alteração de valores. Apenas a emissão garante a reserva.
A30: Taxa de Embarque | D30: Tarifa por pessoa | F30: Quantidade de pessoas | H30: Taxa Serv. | I30: Valor Total
A31: =IF($K$7=DADOS!$J$3,'AÉREO REGULAR'!O12,IF($K$7=DADOS!$J$4,'AÉREO REGULAR'!O27,IF($K$7=DADOS!$J$5,'AÉREO REGULAR'!O42,IF($K$7=DADOS!$J$6,'AÉREO REGULAR'!O57,IF($K$7=DADOS!$J$7,'AÉREO REGULAR'!O72,IF($K$7=DADOS!$J$8,'AÉREO REGULAR'!O87,IF($K$7=DADOS!$J$9,'AÉREO REGULAR'!O102,IF($K$7=DADOS!$J$10,'AÉREO REGULAR'!O117,IF($K$7=DADOS!$J$11,'AÉREO REGULAR'!O132,IF($K$7=DADOS!$J$12,'AÉREO REGULAR'!O147,IF($K$7=DADOS!$J$2," "))))))))))) -> 0 | D31: =IF($K$7=DADOS!$J$3,'AÉREO REGULAR'!O9,IF($K$7=DADOS!$J$4,'AÉREO REGULAR'!O24,IF($K$7=DADOS!$J$5,'AÉREO REGULAR'!O39,IF($K$7=DADOS!$J$6,'AÉREO REGULAR'!O54,IF($K$7=DADOS!$J$7,'AÉREO REGULAR'!O69,IF($K$7=DADOS!$J$8,'AÉREO REGULAR'!O84,IF($K$7=DADOS!$J$9,'AÉREO REGULAR'!O99,IF($K$7=DADOS!$J$10,'AÉREO REGULAR'!O114,IF($K$7=DADOS!$J$11,'AÉREO REGULAR'!O129,IF($K$7=DADOS!$J$12,'AÉREO REGULAR'!O144,IF($K$7=DADOS!$J$2," "))))))))))) -> 0 | F31: =IF($K$7=DADOS!$J$3,'AÉREO REGULAR'!L15,IF($K$7=DADOS!$J$4,'AÉREO REGULAR'!L30,IF($K$7=DADOS!$J$5,'AÉREO REGULAR'!L45,IF($K$7=DADOS!$J$6,'AÉREO REGULAR'!L60,IF($K$7=DADOS!$J$7,'AÉREO REGULAR'!L75,IF($K$7=DADOS!$J$8,'AÉREO REGULAR'!L90,IF($K$7=DADOS!$J$9,'AÉREO REGULAR'!L105,IF($K$7=DADOS!$J$10,'AÉREO REGULAR'!L120,IF($K$7=DADOS!$J$11,'AÉREO REGULAR'!L135,IF($K$7=DADOS!$J$12,'AÉREO REGULAR'!L150,IF($K$7=DADOS!$J$2," "))))))))))) -> 0 | H31: =IF($K$7=DADOS!$J$3,'AÉREO REGULAR'!L13,IF($K$7=DADOS!$J$4,'AÉREO REGULAR'!L28,IF($K$7=DADOS!$J$5,'AÉREO REGULAR'!L43,IF($K$7=DADOS!$J$6,'AÉREO REGULAR'!L58,IF($K$7=DADOS!$J$7,'AÉREO REGULAR'!L73,IF($K$7=DADOS!$J$8,'AÉREO REGULAR'!L88,IF($K$7=DADOS!$J$9,'AÉREO REGULAR'!L103,IF($K$7=DADOS!$J$10,'AÉREO REGULAR'!L118,IF($K$7=DADOS!$J$11,'AÉREO REGULAR'!L133,IF($K$7=DADOS!$J$12,'AÉREO REGULAR'!L148,IF($K$7=DADOS!$J$2," "))))))))))) -> 0.06 | I31: =IF($K$7=DADOS!$J$3,'AÉREO REGULAR'!O19,IF($K$7=DADOS!$J$4,'AÉREO REGULAR'!O34,IF($K$7=DADOS!$J$5,'AÉREO REGULAR'!O49,IF($K$7=DADOS!$J$6,'AÉREO REGULAR'!O64,IF($K$7=DADOS!$J$7,'AÉREO REGULAR'!O79,IF($K$7=DADOS!$J$8,'AÉREO REGULAR'!O94,IF($K$7=DADOS!$J$9,'AÉREO REGULAR'!O109,IF($K$7=DADOS!$J$10,'AÉREO REGULAR'!O124,IF($K$7=DADOS!$J$11,'AÉREO REGULAR'!O139,IF($K$7=DADOS!$J$12,'AÉREO REGULAR'!O154,IF($K$7=DADOS!$J$2," "))))))))))) -> 0
A35: __________________________________________ | H35: ____________________________
B36: Autorizado por | H36: Data da autorização
D38: Avenida das Americas, 3434 - Bloco 5 - Grupo 520 | H38: www.4BTS.com.br
D39: Barra da Tijuca - Rio de Janeiro - 22.640-102 | G39: Tel.: (+55 21) 2025-7900 / (+55 11) 98216-2717

Sheet FICHA DE VOO
A1: PASSAGEIRO | B1: IDA | G1: RETORNO
A2: Nome Completo | B2: DATA | C2: Origem | D2: Destino | E2: Saída | F2: Chegada | G2: DATA2 | H2: Origem2 | I2: Destino2 | J2: Saída 2 | K2: Chegada2
A3: ='AÉREO REGULAR'!U10 -> 0 | B3: ='AÉREO REGULAR'!$F$9 -> 0 | C3: ='AÉREO REGULAR'!G9 -> 0 | D3: =IF('AÉREO REGULAR'!$A$7=0,'AÉREO REGULAR'!H11,IF('AÉREO REGULAR'!$A$7=1,'AÉREO REGULAR'!H10,'AÉREO REGULAR'!H9)) -> 0 | E3: ='AÉREO REGULAR'!$I$9 -> 0 | F3: =IF('AÉREO REGULAR'!$A$7=0,'AÉREO REGULAR'!J11,IF('AÉREO REGULAR'!$A$7=1,'AÉREO REGULAR'!J10,'AÉREO REGULAR'!J9)) -> 0 | G3: ='AÉREO REGULAR'!F13 -> 0 | H3: ='AÉREO REGULAR'!$G$13 -> 0 | I3: =IF('AÉREO REGULAR'!$A$8=0,'AÉREO REGULAR'!H15,IF('AÉREO REGULAR'!$A$8=1,'AÉREO REGULAR'!H14,'AÉREO REGULAR'!H13)) -> 0 | J3: ='AÉREO REGULAR'!I13 -> 0 | K3: =IF('AÉREO REGULAR'!$A$8=0,'AÉREO REGULAR'!J15,IF('AÉREO REGULAR'!$A$8=1,'AÉREO REGULAR'!J14,'AÉREO REGULAR'!J13)) -> 0
A4: ='AÉREO REGULAR'!U11 -> 0 | B4: ='AÉREO REGULAR'!$F$9 -> 0 | C4: ='AÉREO REGULAR'!$G$9 -> 0 | D4: =$D$3 -> 0 | E4: ='AÉREO REGULAR'!$I$9 -> 0 | F4: =F3 -> 0 | G4: =G3 -> 0 | H4: ='AÉREO REGULAR'!$G$13 -> 0 | I4: =I3 -> 0 | J4: =J3 -> 0 | K4: =K3 -> 0
A5: ='AÉREO REGULAR'!U12 -> 0 | B5: ='AÉREO REGULAR'!$F$9 -> 0 | C5: ='AÉREO REGULAR'!$G$9 -> 0 | D5: =$D$3 -> 0 | E5: ='AÉREO REGULAR'!$I$9 -> 0 | F5: =F4 -> 0 | G5: =G4 -> 0 | H5: ='AÉREO REGULAR'!$G$13 -> 0 | I5: =I4 -> 0 | J5: =J4 -> 0 | K5: =K4 -> 0
A6: ='AÉREO REGULAR'!U13 -> 0 | B6: ='AÉREO REGULAR'!$F$9 -> 0 | C6: ='AÉREO REGULAR'!$G$9 -> 0 | D6: =$D$3 -> 0 | E6: ='AÉREO REGULAR'!$I$9 -> 0 | F6: =F5 -> 0 | G6: =G5 -> 0 | H6: ='AÉREO REGULAR'!$G$13 -> 0 | I6: =I5 -> 0 | J6: =J5 -> 0 | K6: =K5 -> 0
A7: ='AÉREO REGULAR'!U14 -> 0 | B7: ='AÉREO REGULAR'!$F$9 -> 0 | C7: ='AÉREO REGULAR'!$G$9 -> 0 | D7: =$D$3 -> 0 | E7: ='AÉREO REGULAR'!$I$9 -> 0 | F7: =F6 -> 0 | G7: =G6 -> 0 | H7: ='AÉREO REGULAR'!$G$13 -> 0 | I7: =I6 -> 0 | J7: =J6 -> 0 | K7: =K6 -> 0
A8: ='AÉREO REGULAR'!U15 -> 0 | B8: ='AÉREO REGULAR'!$F$9 -> 0 | C8: ='AÉREO REGULAR'!$G$9 -> 0 | D8: =$D$3 -> 0 | E8: ='AÉREO REGULAR'!$I$9 -> 0 | F8: =F7 -> 0 | G8: =G7 -> 0 | H8: ='AÉREO REGULAR'!$G$13 -> 0 | I8: =I7 -> 0 | J8: =J7 -> 0 | K8: =K7 -> 0
A9: ='AÉREO REGULAR'!U16 -> 0 | B9: ='AÉREO REGULAR'!$F$9 -> 0 | C9: ='AÉREO REGULAR'!$G$9 -> 0 | D9: =$D$3 -> 0 | E9: ='AÉREO REGULAR'!$I$9 -> 0 | F9: =F8 -> 0 | G9: =G8 -> 0 | H9: ='AÉREO REGULAR'!$G$13 -> 0 | I9: =I8 -> 0 | J9: =J8 -> 0 | K9: =K8 -> 0
A10: ='AÉREO REGULAR'!U17 -> 0 | B10: ='AÉREO REGULAR'!$F$9 -> 0 | C10: ='AÉREO REGULAR'!$G$9 -> 0 | D10: =$D$3 -> 0 | E10: ='AÉREO REGULAR'!$I$9 -> 0 | F10: =F9 -> 0 | G10: =G9 -> 0 | H10: ='AÉREO REGULAR'!$G$13 -> 0 | I10: =I9 -> 0 | J10: =J9 -> 0 | K10: =K9 -> 0
A11: ='AÉREO REGULAR'!U18 -> 0 | B11: ='AÉREO REGULAR'!$F$9 -> 0 | C11: ='AÉREO REGULAR'!$G$9 -> 0 | D11: =$D$3 -> 0 | E11: ='AÉREO REGULAR'!$I$9 -> 0 | F11: =F10 -> 0 | G11: =G10 -> 0 | H11: ='AÉREO REGULAR'!$G$13 -> 0 | I11: =I10 -> 0 | J11: =J10 -> 0 | K11: =K10 -> 0
A12: ='AÉREO REGULAR'!U19 -> 0 | B12: ='AÉREO REGULAR'!$F$9 -> 0 | C12: ='AÉREO REGULAR'!$G$9 -> 0 | D12: =$D$3 -> 0 | E12: ='AÉREO REGULAR'!$I$9 -> 0 | F12: =F11 -> 0 | G12: =G11 -> 0 | H12: ='AÉREO REGULAR'!$G$13 -> 0 | I12: =I11 -> 0 | J12: =J11 -> 0 | K12: =K11 -> 0
A13: ='AÉREO REGULAR'!U25 -> 0 | B13: ='AÉREO REGULAR'!$F$24 -> 0 | C13: ='AÉREO REGULAR'!$G$24 -> 0 | D13: =IF('AÉREO REGULAR'!$A$22=0,'AÉREO REGULAR'!H26,IF('AÉREO REGULAR'!$A$22=1,'AÉREO REGULAR'!H25,'AÉREO REGULAR'!H24)) -> 0 | E13: ='AÉREO REGULAR'!$I$24 -> 0 | F13: =IF('AÉREO REGULAR'!$A$22=0,'AÉREO REGULAR'!J26,IF('AÉREO REGULAR'!$A$22=1,'AÉREO REGULAR'!J25,'AÉREO REGULAR'!J24)) -> 0 | G13: ='AÉREO REGULAR'!$F$28 -> 0 | H13: ='AÉREO REGULAR'!$G$28 -> 0 | I13: =IF('AÉREO REGULAR'!$A$23=0,'AÉREO REGULAR'!H30,IF('AÉREO REGULAR'!$A$23=1,'AÉREO REGULAR'!H29,'AÉREO REGULAR'!H28)) -> 0 | J13: ='AÉREO REGULAR'!I28 -> 0 | K13: =IF('AÉREO REGULAR'!$A$23=0,'AÉREO REGULAR'!J30,IF('AÉREO REGULAR'!$A$23=1,'AÉREO REGULAR'!J29,'AÉREO REGULAR'!J28)) -> 0
A14: ='AÉREO REGULAR'!U26 -> 0 | B14: ='AÉREO REGULAR'!$F$24 -> 0 | C14: ='AÉREO REGULAR'!$G$24 -> 0 | D14: =$D$13 -> 0 | E14: ='AÉREO REGULAR'!$I$24 -> 0 | F14: =$F$13 -> 0 | G14: ='AÉREO REGULAR'!$F$28 -> 0 | H14: ='AÉREO REGULAR'!$G$28 -> 0 | I14: =$I$13 -> 0 | J14: =$J$13 -> 0 | K14: =$K$13 -> 0
A15: ='AÉREO REGULAR'!U27 -> 0 | B15: ='AÉREO REGULAR'!$F$24 -> 0 | C15: ='AÉREO REGULAR'!$G$24 -> 0 | D15: =$D$13 -> 0 | E15: ='AÉREO REGULAR'!$I$24 -> 0 | F15: =$F$13 -> 0 | G15: ='AÉREO REGULAR'!$F$28 -> 0 | H15: ='AÉREO REGULAR'!$G$28 -> 0 | I15: =$I$13 -> 0 | J15: =$J$13 -> 0 | K15: =$K$13 -> 0
A16: ='AÉREO REGULAR'!U28 -> 0 | B16: ='AÉREO REGULAR'!$F$24 -> 0 | C16: ='AÉREO REGULAR'!$G$24 -> 0 | D16: =$D$13 -> 0 | E16: ='AÉREO REGULAR'!$I$24 -> 0 | F16: =$F$13 -> 0 | G16: ='AÉREO REGULAR'!$F$28 -> 0 | H16: ='AÉREO REGULAR'!$G$28 -> 0 | I16: =$I$13 -> 0 | J16: =$J$13 -> 0 | K16: =$K$13 -> 0
A17: ='AÉREO REGULAR'!U29 -> 0 | B17: ='AÉREO REGULAR'!$F$24 -> 0 | C17: ='AÉREO REGULAR'!$G$24 -> 0 | D17: =$D$13 -> 0 | E17: ='AÉREO REGULAR'!$I$24 -> 0 | F17: =$F$13 -> 0 | G17: ='AÉREO REGULAR'!$F$28 -> 0 | H17: ='AÉREO REGULAR'!$G$28 -> 0 | I17: =$I$13 -> 0 | J17: =$J$13 -> 0 | K17: =$K$13 -> 0
A18: ='AÉREO REGULAR'!U30 -> 0 | B18: ='AÉREO REGULAR'!$F$24 -> 0 | C18: ='AÉREO REGULAR'!$G$24 -> 0 | D18: =$D$13 -> 0 | E18: ='AÉREO REGULAR'!$I$24 -> 0 | F18: =$F$13 -> 0 | G18: ='AÉREO REGULAR'!$F$28 -> 0 | H18: ='AÉREO REGULAR'!$G$28 -> 0 | I18: =$I$13 -> 0 | J18: =$J$13 -> 0 | K18: =$K$13 -> 0
A19: ='AÉREO REGULAR'!U31 -> 0 | B19: ='AÉREO REGULAR'!$F$24 -> 0 | C19: ='AÉREO REGULAR'!$G$24 -> 0 | D19: =$D$13 -> 0 | E19: ='AÉREO REGULAR'!$I$24 -> 0 | F19: =$F$13 -> 0 | G19: ='AÉREO REGULAR'!$F$28 -> 0 | H19: ='AÉREO REGULAR'!$G$28 -> 0 | I19: =$I$13 -> 0 | J19: =$J$13 -> 0 | K19: =$K$13 -> 0
A20: ='AÉREO REGULAR'!U32 -> 0 | B20: ='AÉREO REGULAR'!$F$24 -> 0 | C20: ='AÉREO REGULAR'!$G$24 -> 0 | D20: =$D$13 -> 0 | E20: ='AÉREO REGULAR'!$I$24 -> 0 | F20: =$F$13 -> 0 | G20: ='AÉREO REGULAR'!$F$28 -> 0 | H20: ='AÉREO REGULAR'!$G$28 -> 0 | I20: =$I$13 -> 0 | J20: =$J$13 -> 0 | K20: =$K$13 -> 0
A21: ='AÉREO REGULAR'!U33 -> 0 | B21: ='AÉREO REGULAR'!$F$24 -> 0 | C21: ='AÉREO REGULAR'!$G$24 -> 0 | D21: =$D$13 -> 0 | E21: ='AÉREO REGULAR'!$I$24 -> 0 | F21: =$F$13 -> 0 | G21: ='AÉREO REGULAR'!$F$28 -> 0 | H21: ='AÉREO REGULAR'!$G$28 -> 0 | I21: =$I$13 -> 0 | J21: =$J$13 -> 0 | K21: =$K$13 -> 0
A22: ='AÉREO REGULAR'!U34 -> 0 | B22: ='AÉREO REGULAR'!$F$24 -> 0 | C22: ='AÉREO REGULAR'!$G$24 -> 0 | D22: =$D$13 -> 0 | E22: ='AÉREO REGULAR'!$I$24 -> 0 | F22: =$F$13 -> 0 | G22: ='AÉREO REGULAR'!$F$28 -> 0 | H22: ='AÉREO REGULAR'!$G$28 -> 0 | I22: =$I$13 -> 0 | J22: =$J$13 -> 0 | K22: =$K$13 -> 0
A23: ='AÉREO REGULAR'!U40 -> 0 | B23: ='AÉREO REGULAR'!$F$39 -> 0 | C23: ='AÉREO REGULAR'!$G$39 -> 0 | D23: =IF('AÉREO REGULAR'!$A$37=0,'AÉREO REGULAR'!H41,IF('AÉREO REGULAR'!$A$37=1,'AÉREO REGULAR'!H40,'AÉREO REGULAR'!H39)) -> 0 | E23: ='AÉREO REGULAR'!$I$39 -> 0 | F23: =IF('AÉREO REGULAR'!$A$37=0,'AÉREO REGULAR'!J41,IF('AÉREO REGULAR'!$A$37=1,'AÉREO REGULAR'!J40,'AÉREO REGULAR'!J39)) -> 0 | G23: ='AÉREO REGULAR'!$I$43 -> 0 | H23: ='AÉREO REGULAR'!$G$43 -> 0 | I23: =IF('AÉREO REGULAR'!$A$37=0,'AÉREO REGULAR'!H45,IF('AÉREO REGULAR'!$A$37=1,'AÉREO REGULAR'!H44,'AÉREO REGULAR'!H43)) -> 0 | J23: ='AÉREO REGULAR'!$I$43 -> 0 | K23: =IF('AÉREO REGULAR'!$A$37=0,'AÉREO REGULAR'!J45,IF('AÉREO REGULAR'!$A$37=1,'AÉREO REGULAR'!J44,'AÉREO REGULAR'!J43)) -> 0
A24: ='AÉREO REGULAR'!U41 -> 0 | B24: ='AÉREO REGULAR'!$F$39 -> 0 | C24: ='AÉREO REGULAR'!$G$39 -> 0 | D24: =$D$23 -> 0 | E24: ='AÉREO REGULAR'!$I$39 -> 0 | F24: =$F$23 -> 0 | G24: ='AÉREO REGULAR'!$I$43 -> 0 | H24: ='AÉREO REGULAR'!$G$43 -> 0 | I24: =$I$23 -> 0 | J24: ='AÉREO REGULAR'!$I$43 -> 0 | K24: =$K$23 -> 0
A25: ='AÉREO REGULAR'!U42 -> 0 | B25: ='AÉREO REGULAR'!$F$39 -> 0 | C25: ='AÉREO REGULAR'!$G$39 -> 0 | D25: =$D$23 -> 0 | E25: ='AÉREO REGULAR'!$I$39 -> 0 | F25: =$F$23 -> 0 | G25: ='AÉREO REGULAR'!$I$43 -> 0 | H25: ='AÉREO REGULAR'!$G$43 -> 0 | I25: =$I$23 -> 0 | J25: ='AÉREO REGULAR'!$I$43 -> 0 | K25: =$K$23 -> 0
A26: ='AÉREO REGULAR'!U43 -> 0 | B26: ='AÉREO REGULAR'!$F$39 -> 0 | C26: ='AÉREO REGULAR'!$G$39 -> 0 | D26: =$D$23 -> 0 | E26: ='AÉREO REGULAR'!$I$39 -> 0 | F26: =$F$23 -> 0 | G26: ='AÉREO REGULAR'!$I$43 -> 0 | H26: ='AÉREO REGULAR'!$G$43 -> 0 | I26: =$I$23 -> 0 | J26: ='AÉREO REGULAR'!$I$43 -> 0 | K26: =$K$23 -> 0
A27: ='AÉREO REGULAR'!U44 -> 0 | B27: ='AÉREO REGULAR'!$F$39 -> 0 | C27: ='AÉREO REGULAR'!$G$39 -> 0 | D27: =$D$23 -> 0 | E27: ='AÉREO REGULAR'!$I$39 -> 0 | F27: =$F$23 -> 0 | G27: ='AÉREO REGULAR'!$I$43 -> 0 | H27: ='AÉREO REGULAR'!$G$43 -> 0 | I27: =$I$23 -> 0 | J27: ='AÉREO REGULAR'!$I$43 -> 0 | K27: =$K$23 -> 0
A28: ='AÉREO REGULAR'!U45 -> 0 | B28: ='AÉREO REGULAR'!$F$39 -> 0 | C28: ='AÉREO REGULAR'!$G$39 -> 0 | D28: =$D$23 -> 0 | E28: ='AÉREO REGULAR'!$I$39 -> 0 | F28: =$F$23 -> 0 | G28: ='AÉREO REGULAR'!$I$43 -> 0 | H28: ='AÉREO REGULAR'!$G$43 -> 0 | I28: =$I$23 -> 0 | J28: ='AÉREO REGULAR'!$I$43 -> 0 | K28: =$K$23 -> 0
A29: ='AÉREO REGULAR'!U46 -> 0 | B29: ='AÉREO REGULAR'!$F$39 -> 0 | C29: ='AÉREO REGULAR'!$G$39 -> 0 | D29: =$D$23 -> 0 | E29: ='AÉREO REGULAR'!$I$39 -> 0 | F29: =$F$23 -> 0 | G29: ='AÉREO REGULAR'!$I$43 -> 0 | H29: ='AÉREO REGULAR'!$G$43 -> 0 | I29: =$I$23 -> 0 | J29: ='AÉREO REGULAR'!$I$43 -> 0 | K29: =$K$23 -> 0
A30: ='AÉREO REGULAR'!U47 -> 0 | B30: ='AÉREO REGULAR'!$F$39 -> 0 | C30: ='AÉREO REGULAR'!$G$39 -> 0 | D30: =$D$23 -> 0 | E30: ='AÉREO REGULAR'!$I$39 -> 0 | F30: =$F$23 -> 0 | G30: ='AÉREO REGULAR'!$I$43 -> 0 | H30: ='AÉREO REGULAR'!$G$43 -> 0 | I30: =$I$23 -> 0 | J30: ='AÉREO REGULAR'!$I$43 -> 0 | K30: =$K$23 -> 0
A31: ='AÉREO REGULAR'!U48 -> 0 | B31: ='AÉREO REGULAR'!$F$39 -> 0 | C31: ='AÉREO REGULAR'!$G$39 -> 0 | D31: =$D$23 -> 0 | E31: ='AÉREO REGULAR'!$I$39 -> 0 | F31: =$F$23 -> 0 | G31: ='AÉREO REGULAR'!$I$43 -> 0 | H31: ='AÉREO REGULAR'!$G$43 -> 0 | I31: =$I$23 -> 0 | J31: ='AÉREO REGULAR'!$I$43 -> 0 | K31: =$K$23 -> 0
A32: ='AÉREO REGULAR'!U49 -> 0 | B32: ='AÉREO REGULAR'!$F$39 -> 0 | C32: ='AÉREO REGULAR'!$G$39 -> 0 | D32: =$D$23 -> 0 | E32: ='AÉREO REGULAR'!$I$39 -> 0 | F32: =$F$23 -> 0 | G32: ='AÉREO REGULAR'!$I$43 -> 0 | H32: ='AÉREO REGULAR'!$G$43 -> 0 | I32: =$I$23 -> 0 | J32: ='AÉREO REGULAR'!$I$43 -> 0 | K32: =$K$23 -> 0
A33: ='AÉREO REGULAR'!U55 -> 0 | B33: ='AÉREO REGULAR'!$F$54 -> 0 | C33: ='AÉREO REGULAR'!$G$54 -> 0 | D33: =IF('AÉREO REGULAR'!$A$52=0,'AÉREO REGULAR'!H56,IF('AÉREO REGULAR'!$A$52=1,'AÉREO REGULAR'!H55,'AÉREO REGULAR'!H54)) -> 0 | E33: ='AÉREO REGULAR'!$I$54 -> 0 | F33: =IF('AÉREO REGULAR'!$A$52=0,'AÉREO REGULAR'!J56,IF('AÉREO REGULAR'!$A$52=1,'AÉREO REGULAR'!J55,'AÉREO REGULAR'!J54)) -> 0 | G33: ='AÉREO REGULAR'!$F$58 -> 0 | H33: ='AÉREO REGULAR'!$G$58 -> 0 | I33: =IF('AÉREO REGULAR'!$A$53=0,'AÉREO REGULAR'!H60,IF('AÉREO REGULAR'!$A$53=1,'AÉREO REGULAR'!H59,'AÉREO REGULAR'!H58)) -> 0 | J33: ='AÉREO REGULAR'!$I$58 -> 0 | K33: =IF('AÉREO REGULAR'!$A$53=0,'AÉREO REGULAR'!J60,IF('AÉREO REGULAR'!$A$53=1,'AÉREO REGULAR'!J59,'AÉREO REGULAR'!J58)) -> 0
A34: ='AÉREO REGULAR'!U56 -> 0 | B34: ='AÉREO REGULAR'!$F$54 -> 0 | C34: ='AÉREO REGULAR'!$G$54 -> 0 | D34: =$D$33 -> 0 | E34: ='AÉREO REGULAR'!$I$54 -> 0 | F34: =$F$33 -> 0 | G34: ='AÉREO REGULAR'!$F$58 -> 0 | H34: ='AÉREO REGULAR'!$G$58 -> 0 | I34: =$I$33 -> 0 | J34: ='AÉREO REGULAR'!$I$58 -> 0 | K34: =$K$33 -> 0
A35: ='AÉREO REGULAR'!U57 -> 0 | B35: ='AÉREO REGULAR'!$F$54 -> 0 | C35: ='AÉREO REGULAR'!$G$54 -> 0 | D35: =$D$33 -> 0 | E35: ='AÉREO REGULAR'!$I$54 -> 0 | F35: =$F$33 -> 0 | G35: ='AÉREO REGULAR'!$F$58 -> 0 | H35: ='AÉREO REGULAR'!$G$58 -> 0 | I35: =$I$33 -> 0 | J35: ='AÉREO REGULAR'!$I$58 -> 0 | K35: =$K$33 -> 0
A36: ='AÉREO REGULAR'!U58 -> 0 | B36: ='AÉREO REGULAR'!$F$54 -> 0 | C36: ='AÉREO REGULAR'!$G$54 -> 0 | D36: =$D$33 -> 0 | E36: ='AÉREO REGULAR'!$I$54 -> 0 | F36: =$F$33 -> 0 | G36: ='AÉREO REGULAR'!$F$58 -> 0 | H36: ='AÉREO REGULAR'!$G$58 -> 0 | I36: =$I$33 -> 0 | J36: ='AÉREO REGULAR'!$I$58 -> 0 | K36: =$K$33 -> 0
A37: ='AÉREO REGULAR'!U59 -> 0 | B37: ='AÉREO REGULAR'!$F$54 -> 0 | C37: ='AÉREO REGULAR'!$G$54 -> 0 | D37: =$D$33 -> 0 | E37: ='AÉREO REGULAR'!$I$54 -> 0 | F37: =$F$33 -> 0 | G37: ='AÉREO REGULAR'!$F$58 -> 0 | H37: ='AÉREO REGULAR'!$G$58 -> 0 | I37: =$I$33 -> 0 | J37: ='AÉREO REGULAR'!$I$58 -> 0 | K37: =$K$33 -> 0
A38: ='AÉREO REGULAR'!U60 -> 0 | B38: ='AÉREO REGULAR'!$F$54 -> 0 | C38: ='AÉREO REGULAR'!$G$54 -> 0 | D38: =$D$33 -> 0 | E38: ='AÉREO REGULAR'!$I$54 -> 0 | F38: =$F$33 -> 0 | G38: ='AÉREO REGULAR'!$F$58 -> 0 | H38: ='AÉREO REGULAR'!$G$58 -> 0 | I38: =$I$33 -> 0 | J38: ='AÉREO REGULAR'!$I$58 -> 0 | K38: =$K$33 -> 0
A39: ='AÉREO REGULAR'!U61 -> 0 | B39: ='AÉREO REGULAR'!$F$54 -> 0 | C39: ='AÉREO REGULAR'!$G$54 -> 0 | D39: =$D$33 -> 0 | E39: ='AÉREO REGULAR'!$I$54 -> 0 | F39: =$F$33 -> 0 | G39: ='AÉREO REGULAR'!$F$58 -> 0 | H39: ='AÉREO REGULAR'!$G$58 -> 0 | I39: =$I$33 -> 0 | J39: ='AÉREO REGULAR'!$I$58 -> 0 | K39: =$K$33 -> 0
A40: ='AÉREO REGULAR'!U62 -> 0 | B40: ='AÉREO REGULAR'!$F$54 -> 0 | C40: ='AÉREO REGULAR'!$G$54 -> 0 | D40: =$D$33 -> 0 | E40: ='AÉREO REGULAR'!$I$54 -> 0 | F40: =$F$33 -> 0 | G40: ='AÉREO REGULAR'!$F$58 -> 0 | H40: ='AÉREO REGULAR'!$G$58 -> 0 | I40: =$I$33 -> 0 | J40: ='AÉREO REGULAR'!$I$58 -> 0 | K40: =$K$33 -> 0
...

Sheet DADOS
B1: MOEDA | C1: DU | D1: Responsavel | E1: Data | F1: Bagagem | G1: CABINE | H1: STATUS | J1: PROPOSTA
C2: 0 | E2: =TODAY() -> 46127 | F2: APENAS DE MÃO | G2: ECONÔMICA | H2: COTAÇÃO | J2: S/O
B3: Reais | C3: 0.06 | D3: Consuelo | E3: =E2+1 -> 46128 | F3: 1 - 23KG | G3: PRIMEIRA | H3: CONFIRMADO | J3: OPÇÃO 1
B4: Dollar | C4: =C3+1% -> 0.07 | D4: Cristiane | E4: =E3+1 -> 46129 | F4: 2 - 23KG | G4: EXECUTIVA | H4: EMITIDO | J4: OPÇÃO 2
B5: Euro | C5: =C4+1% -> 0.08 | D5: Wallace | E5: =E4+1 -> 46130 | F5: 3 - 23KG | G5: ECONÔMICA P | H5: CANCELADO | J5: OPÇÃO 3
C6: =C5+1% -> 0.09 | D6: Jorge | E6: =E5+1 -> 46131 | F6: 1 - 32KG | H6: RESERVADO | J6: OPÇÃO 4
C7: =C6+1% -> 0.1 | D7: Alessandra | E7: =E6+1 -> 46132 | F7: 2 - 32KG | J7: OPÇÃO 5
C8: =C7+1% -> 0.11 | D8: Amir | E8: =E7+1 -> 46133 | F8: 3 - 32KG | J8: OPÇÃO 6
C9: =C8+1% -> 0.12 | D9: Humberto | E9: =E8+1 -> 46134 | F9: 1 - 40KG | J9: OPÇÃO 7
C10: =C9+1% -> 0.13 | D10: Taiane | E10: =E9+1 -> 46135 | F10: 2 - 40KG | J10: OPÇÃO 8
E11: =E10+1 -> 46136 | F11: 3 - 40KG | J11: OPÇÃO 9
E12: =E11+1 -> 46137 | J12: OPÇÃO 10
E13: =E12+1 -> 46138
E14: =E13+1 -> 46139
E15: =E14+1 -> 46140
E16: =E15+1 -> 46141
E17: =E16+1 -> 46142
E18: =E17+1 -> 46143
E19: =E18+1 -> 46144
E20: =E19+1 -> 46145
E21: =E20+1 -> 46146
E22: =E21+1 -> 46147
E23: =E22+1 -> 46148
E24: =E23+1 -> 46149
... E180: =E179+1 -> 46305
